File: Tensile-Tests-Data/WAGNERSIL 20 NF.csv
PARAMETER;INFO;URL;;
Specimen Thickness (mm);3;;;
Specimen Width (mm);6;;;
Specimen Length (mm);33;;;
Specimen Cross-section (cm^2);0.18;;;
Standard;ASTM D412;;;
Type of test;Pull-to-failure;;;
Speed (mm/min);500;;;
Machine;Instron 68SC-2;;;
Load Cell;1 kN - Instron  2525-806;;;
Grippers;;;;
Strain Measurement;Global;;;
Strain calculation;Derived from the machine crosshead displacement readings;;;
Lab;Univ. Savoie Mont Blanc - SYMME Lab, 7400 Annecy, France;;;
Material supplier;Smooth-On;https://www.zahntechnikshop.de/p/wagnersil-r-20-nf-premium-dubliersilikon-silikonkautschuk-2x1-kg-2-kg;;
Material;WAGNERSIL 20 NF;;;
;;;;
Time (s);True Strain;True Stress (MPa);Engineering Strain;Engineering Stress (MPa)
0;0;0.0000555555555555556;0;0.0000555555555555556
0.02;0.0000545439669963159;0.00492249070707071;0.0000545454545454553;0.00492222222222222
0.04;0.0012295468277053;0.00174659063973064;0.00123030303030303;0.00174444444444445
0.06;0.00510211356945143;0.00227267703703704;0.00511515151515152;0.00226111111111111
0.08;0.010439260212617;0.00981863277777778;0.0104939393939394;0.00971666666666667
0.1;0.0156824457051305;0.00624720727272727;0.0158060606060606;0.00615
0.12;0.020622255658441;0.00939169454545455;0.0208363636363636;0.0092
0.14;0.025437346293847;0.0088956502020202;0.0257636363636364;0.00867222222222222
0.16;0.0302293628906453;0.0138799709090909;0.0306909090909091;0.0134666666666667
0.18;0.0350248599226098;0.016017983030303;0.0356454545454545;0.0154666666666667
0.2;0.0398178541764068;0.0146554154040404;0.0406212121212121;0.0140833333333333
0.22;0.0446111701546248;0.0171772329124579;0.0456212121212121;0.0164277777777778
0.24;0.0493845041089708;0.0184618026599327;0.0506242424242424;0.0175722222222222
0.26;0.0541409027662541;0.0183093737037037;0.0556333333333333;0.0173444444444444
0.28;0.0588862132637817;0.0182020105050505;0.0606545454545454;0.0171611111111111
0.3;0.0636147991832338;0.0216215;0.0656818181818182;0.0202888888888889
0.32;0.06832113076815;0.0262145275757576;0.0707090909090909;0.0244833333333333
0.34;0.0730082334636088;0.0255786922558923;0.0757393939393939;0.0237777777777778
0.36;0.0776762735119495;0.0267551292929293;0.0807727272727273;0.0247555555555556
0.38;0.0823309966331062;0.0295221075084175;0.0858151515151515;0.0271888888888889
0.4;0.0869641536524033;0.0333681211784512;0.0908575757575758;0.0305888888888889
0.42;0.0915731783560661;0.0308616763299663;0.0958969696969697;0.0281611111111111
0.44;0.096161057374733;0.0325449021717172;0.100936363636364;0.0295611111111111
0.46;0.100730723783118;0.0364051351010101;0.105978787878788;0.0329166666666667
0.48;0.105282330783287;0.0370341414141414;0.111024242424242;0.0333333333333333
0.5;0.109810599331438;0.0377974577777778;0.116066666666667;0.0338666666666667
0.52;0.114323860951086;0.0390148072727273;0.121115151515152;0.0348
0.54;0.118816844526141;0.0423124704040404;0.126163636363636;0.0375722222222222
0.56;0.123292410267032;0.0425902504545455;0.131215151515152;0.03765
0.58;0.127745367637658;0.0424268216666667;0.136263636363636;0.0373388888888889
0.6;0.132178584052099;0.0465718751683502;0.141312121212121;0.0408055555555556
0.62;0.136597520579669;0.0504719768518519;0.146366666666667;0.0440277777777778
0.64;0.140994384187684;0.0503233713131313;0.151418181818182;0.0437055555555556
0.66;0.145361518711342;0.0516101317003367;0.156457575757576;0.0446277777777778
0.68;0.149709664268376;0.0549323539057239;0.16149696969697;0.0472944444444444
0.7;0.154044180649929;0.0561949408922559;0.166542424242424;0.0481722222222222
0.72;0.158367749502553;0.0563538142424242;0.17159696969697;0.0481
0.74;0.162667554816121;0.0585381113636364;0.176645454545455;0.04975
0.76;0.166943822174225;0.0611786074579125;0.181687878787879;0.0517722222222222
0.78;0.171201880907131;0.0628769272222222;0.186730303030303;0.0529833333333333
0.8;0.175439342736048;0.0633690431649832;0.191769696969697;0.0531722222222222
0.82;0.179663988180625;0.0673009053535353;0.196815151515151;0.0562333333333333
0.84;0.183873382392558;0.0701087121212121;0.201863636363636;0.0583333333333333
0.86;0.188067642639599;0.0684656145117845;0.206915151515152;0.0567277777777778
0.88;0.192249385143718;0.0699240931818182;0.211972727272727;0.0576944444444445
0.9;0.19641869329307;0.0732926343434344;0.217036363636364;0.0602222222222222
0.92;0.200565731275918;0.0756951407239057;0.222093939393939;0.0619388888888889
0.94;0.204688234169772;0.0768327506734007;0.227142424242424;0.0626111111111111
0.96;0.208796271061598;0.0771490316498317;0.232193939393939;0.0626111111111111
0.98;0.212892399461366;0.0804557165824916;0.237251515151515;0.0650277777777778
1;0.216969378762228;0.0834139502693603;0.242306060606061;0.0671444444444444
1.02;0.221027374396507;0.0838293588552189;0.247357575757576;0.0672055555555556
1.04;0.225068969234164;0.0864579742424243;0.252409090909091;0.0690333333333333
1.06;0.229094295312666;0.089733786026936;0.257460606060606;0.0713611111111111
1.08;0.233103483081385;0.089897876986532;0.262512121212121;0.0712055555555556
1.1;0.237091880112342;0.0919683441077441;0.267557575757576;0.0725555555555556
1.12;0.241073957698179;0.0955026970370371;0.272615151515152;0.0750444444444445
1.14;0.24504024121454;0.0977774545454545;0.277672727272727;0.0765277777777778
1.16;0.248979043458747;0.0979994375757576;0.282715151515151;0.0764
1.18;0.25290474554737;0.100116232895623;0.287760606060606;0.0777444444444444
1.2;0.256819784678334;0.102196798181818;0.292812121212121;0.07905
1.22;0.260721890868998;0.104608053333333;0.297866666666667;0.0806
1.24;0.264599526644337;0.105173717171717;0.302909090909091;0.0807222222222222
1.26;0.268462184420998;0.108610840538721;0.307951515151515;0.0830388888888889
1.28;0.272314595320659;0.113472377777778;0.313;0.0864222222222222
1.3;0.276152222086923;0.114391963501684;0.318048484848485;0.0867888888888889
1.32;0.279977468066228;0.116557759444444;0.3231;0.0880944444444444
1.34;0.283790418872511;0.119032161818182;0.328154545454545;0.0896222222222222
1.36;0.287582067451448;0.120758293333333;0.3332;0.0905777777777778
1.38;0.291354864939114;0.122285341952862;0.338239393939394;0.0913777777777778
1.4;0.295115737807124;0.123544613888889;0.343281818181818;0.0919722222222222
1.42;0.298869261842345;0.126061675925926;0.348333333333333;0.0934944444444445
1.44;0.302610988656389;0.129346287104377;0.353387878787879;0.0955722222222222
1.46;0.306334305678049;0.130696671919192;0.358436363636364;0.0962111111111111
1.48;0.310050478404694;0.133683005791246;0.363493939393939;0.0980444444444444
1.5;0.313755106544664;0.136574140555556;0.368554545454545;0.0997944444444444
1.52;0.317441648888118;0.139360273434343;0.373609090909091;0.101455555555556
1.54;0.321110254529993;0.141289423888889;0.378657575757576;0.102483333333333
1.56;0.324767640671685;0.143997992727273;0.383709090909091;0.104066666666667
1.58;0.328418245107627;0.147649364949495;0.388769696969697;0.106316666666667
1.6;0.332053397004955;0.149720279545455;0.393827272727273;0.107416666666667
1.62;0.335673216190691;0.15184084979798;0.398881818181818;0.108544444444444
1.64;0.339279979531083;0.154518796111111;0.403936363636364;0.110061111111111
1.66;0.342869479476786;0.156608665909091;0.408984848484848;0.11115
1.68;0.346448284001108;0.158874841212121;0.414036363636364;0.112355555555556
1.7;0.350012190953248;0.162832102558923;0.419084848484848;0.114744444444444
1.72;0.353563441565294;0.165745384444444;0.424133333333333;0.116383333333333
1.74;0.357102125411006;0.16668229949495;0.429181818181818;0.116627777777778
1.76;0.360621992568379;0.170377512104377;0.434221212121212;0.118794444444444
1.78;0.364129513704598;0.173998611380471;0.439260606060606;0.120894444444444
1.8;0.367631069440902;0.176550738484849;0.444309090909091;0.122238888888889
1.82;0.371124588626858;0.178964201010101;0.449363636363636;0.123477777777778
1.84;0.374603862095251;0.180363638956229;0.454415151515151;0.124011111111111
1.86;0.378071072179462;0.184557668148148;0.459466666666667;0.126455555555556
1.88;0.381522163941137;0.188555935606061;0.464512121212121;0.12875
1.9;0.384961386618027;0.190944514343434;0.469557575757576;0.129933333333333
1.92;0.388394986539711;0.194689761447811;0.474612121212121;0.132027777777778
1.94;0.391816837183789;0.197584822222222;0.479666666666667;0.133533333333333
1.96;0.395220895692201;0.200180435942761;0.484712121212121;0.134827777777778
1.98;0.398609337695292;0.203135895488215;0.489751515151515;0.136355555555556
2;0.401992418629192;0.206083093333333;0.4948;0.137866666666667
2.02;0.40536813370933;0.210504585454545;0.499854545454545;0.14035
2.04;0.408734505274823;0.214341289175084;0.504912121212121;0.142427777777778
2.06;0.412085568658473;0.215404701414141;0.509963636363636;0.142655555555556
2.08;0.415429440263454;0.218348223804714;0.515021212121212;0.144122222222222
2.1;0.418762167645624;0.222539534545455;0.520078787878788;0.1464
2.12;0.422079851019227;0.223829817861953;0.525130303030303;0.146761111111111
2.14;0.425382603039326;0.228429737676768;0.530175757575758;0.149283333333333
2.16;0.428676456639465;0.23331143973064;0.535224242424242;0.151972222222222
2.18;0.431965398502659;0.235166805151515;0.540281818181818;0.152677777777778
2.2;0.43524551960643;0.237939807154882;0.545342424242424;0.153972222222222
2.22;0.438509053087088;0.24218875993266;0.550393939393939;0.156211111111111
2.24;0.441758074166023;0.247401276936027;0.555439393939394;0.159055555555556
2.26;0.444998515180349;0.249712738114478;0.560487878787879;0.160022222222222
2.28;0.448228489643819;0.251346863181818;0.565536363636364;0.16055
2.3;0.451446135539802;0.255551112727273;0.570581818181818;0.162711111111111
2.32;0.454659231079292;0.259542323232323;0.575636363636364;0.164722222222222
2.34;0.457863952765906;0.262755240892256;0.580693939393939;0.166227777777778
2.36;0.461052704123279;0.266501633754209;0.585742424242424;0.168061111111111
2.38;0.464231319657492;0.271061933181818;0.590790909090909;0.170394444444444
2.4;0.467399863600254;0.273349556632997;0.595839393939394;0.171288888888889
2.42;0.470560292461832;0.27723873010101;0.600890909090909;0.173177777777778
2.44;0.473706990602753;0.281404660252525;0.605936363636364;0.175227777777778
2.46;0.476843818086344;0.285725525252525;0.610981818181818;0.177361111111111
2.48;0.479976462095957;0.289378244848485;0.616036363636364;0.179066666666667
2.5;0.483097453984811;0.292336180808081;0.621087878787879;0.180333333333333
2.52;0.486206872084199;0.297781704545454;0.626136363636364;0.183122222222222
2.54;0.489308509394613;0.300229191245791;0.631187878787879;0.184055555555556
2.56;0.492400556289349;0.302595205252525;0.636239393939394;0.184933333333333
2.58;0.495477533000992;0.307658276818182;0.641281818181818;0.18745
2.6;0.498545070962342;0.31158515537037;0.646324242424242;0.189261111111111
2.62;0.501610567986387;0.316532616329966;0.651378787878788;0.191677777777778
2.64;0.504666696450407;0.320188563333333;0.656433333333333;0.1933
2.66;0.507708041881053;0.323785294006734;0.661478787878788;0.194877777777778
2.68;0.510747438891451;0.327881771010101;0.666536363636364;0.196744444444444
2.7;0.513781251591623;0.33058676;0.6716;0.197766666666667
2.72;0.516802273415465;0.334511815892256;0.676657575757576;0.199511111111111
2.74;0.519801582683226;0.339832974175084;0.681693939393939;0.202077777777778
2.76;0.522791922988891;0.342415622239057;0.686730303030303;0.203005555555556
2.78;0.525782303804267;0.345377258181818;0.691781818181818;0.20415
2.8;0.528767340606209;0.349850575488215;0.696839393939394;0.206177777777778
2.82;0.531743493475731;0.354807698249158;0.70189696969697;0.208477777777778
2.84;0.534709039865573;0.358668445589226;0.706951515151515;0.210122222222222
2.86;0.53766227771955;0.361821688888889;0.712;0.211344444444444
2.88;0.540608584465558;0.366266166531987;0.717051515151515;0.213311111111111
2.9;0.543544476328717;0.371122117222222;0.7221;0.215505555555556
2.92;0.546471773956435;0.373409502424243;0.727148484848485;0.2162
2.94;0.549390527517693;0.375819379208754;0.73219696969697;0.216961111111111
2.96;0.552299042427097;0.379336534680135;0.737242424242424;0.218355555555556
2.98;0.55520260093177;0.384369401851852;0.742293939393939;0.220611111111111
3;0.558097753186603;0.389891015757576;0.747345454545455;0.223133333333333
3.02;0.560986276957606;0.395283026666667;0.7524;0.225566666666667
3.04;0.563866481184467;0.398756672727273;0.757454545454545;0.226894444444444
3.06;0.566734975023677;0.40201714952862;0.76250303030303;0.228094444444444
3.08;0.569595264135581;0.407705396430976;0.767551515151515;0.230661111111111
3.1;0.572443976267427;0.410936513872054;0.772593939393939;0.231827777777778
3.12;0.575288005641405;0.417192925387205;0.777642424242424;0.234688888888889
3.14;0.578120569744434;0.42012929976431;0.782684848484848;0.235672222222222
3.16;0.580946828142869;0.421656055639731;0.787730303030303;0.235861111111111
3.18;0.583766811595442;0.427089706683502;0.792778787878788;0.238227777777778
3.2;0.586578865098429;0.432127760858586;0.797827272727273;0.240361111111111
3.22;0.589384713940637;0.437258202020202;0.802878787878788;0.242533333333333
3.24;0.592187740356922;0.441920652525253;0.807939393939394;0.244433333333333
3.26;0.594976246029393;0.445833863703704;0.812987878787879;0.245911111111111
3.28;0.597758664354071;0.450378858973064;0.818039393939394;0.247727777777778
3.3;0.600536686655405;0.454923463838384;0.82309696969697;0.249533333333333
3.32;0.60331032806789;0.458624557373737;0.828160606060606;0.250866666666667
3.34;0.606069685682097;0.465024808080808;0.833212121212121;0.253666666666667
3.36;0.608819801728363;0.469859410909091;0.838260606060606;0.2556
3.38;0.611565663263321;0.472646486127946;0.843315151515151;0.256411111111111
3.4;0.614305645129492;0.478163755808081;0.848372727272727;0.258694444444444
3.42;0.617034870059144;0.482734640740741;0.853424242424242;0.260455555555556
3.44;0.619756666589254;0.488469378282828;0.858475757575758;0.262833333333333
3.46;0.622469448934524;0.492042870387205;0.863524242424242;0.264038888888889
3.48;0.625174891997129;0.494839582020202;0.868572727272727;0.264822222222222
3.5;0.62787303538199;0.500465043771044;0.873621212121212;0.267111111111111
3.52;0.630567144378488;0.505301156262626;0.878675757575758;0.268966666666667
3.54;0.633254014649251;0.511642080639731;0.883730303030303;0.271611111111111
3.56;0.635930476251087;0.519235782003367;0.888778787878788;0.274905555555556
3.58;0.638599793523486;0.522780497373737;0.893827272727273;0.276044444444444
3.6;0.641260408664045;0.526346421414141;0.898872727272727;0.277188888888889
3.62;0.643915555324551;0.529977624074074;0.903921212121212;0.278361111111111
3.64;0.646565258246969;0.533876039393939;0.908972727272727;0.279666666666667
3.66;0.649204792368184;0.539274622727273;0.914018181818182;0.28175
3.68;0.651838956738269;0.544151353333333;0.919066666666667;0.28355
3.7;0.654466200512421;0.549644872087542;0.924115151515151;0.285661111111111
3.72;0.657084989172452;0.556369918787879;0.929160606060606;0.2884
3.74;0.659695370995306;0.562100891750842;0.93420303030303;0.290611111111111
3.76;0.662298956462134;0.566065748181818;0.939245454545455;0.2919
3.78;0.664898898000111;0.571590013282828;0.944293939393939;0.293983333333333
3.8;0.667493651892108;0.576573066666667;0.949345454545455;0.295777777777778
3.82;0.670083240961394;0.582693502222222;0.9544;0.298144444444444
3.84;0.67266768787843;0.587761071599327;0.959457575757576;0.299961111111111
3.86;0.675247015162239;0.590512337474748;0.964518181818182;0.300588888888889
3.88;0.677815090956878;0.598267737508418;0.969569696969697;0.303755555555556
3.9;0.680376588627744;0.6051117003367;0.974621212121212;0.306444444444444
3.92;0.682933072496385;0.608970259427609;0.979675757575757;0.307611111111111
3.94;0.685481510607667;0.614692088888889;0.984727272727273;0.309711111111111
3.96;0.688018901873167;0.618641507340067;0.989769696969697;0.310911111111111
3.98;0.69055442834154;0.623636522609428;0.994821212121212;0.312627777777778
4;0.693086572662718;0.628795222222222;0.999878787878788;0.314416666666667
4.02;0.695612321420114;0.633314843131313;1.00493636363636;0.315877777777778
4.04;0.698130199220413;0.640584102727273;1.00999090909091;0.3187
4.06;0.700635737859007;0.646702559074074;1.01503333333333;0.320938888888889
4.08;0.703136514552871;0.652249772626263;1.02007878787879;0.322883333333333
4.1;0.705632549312995;0.659133924444445;1.02512727272727;0.325477777777778
4.12;0.708123862022204;0.663597773131313;1.03017878787879;0.326866666666667
4.14;0.71060749458846;0.668933977272727;1.03522727272727;0.328677777777778
4.16;0.713084974003004;0.676725464191919;1.04027575757576;0.331683333333333
4.18;0.715557812253899;0.680957626666667;1.04532727272727;0.332933333333333
4.2;0.718024550656616;0.685749185606061;1.05037878787879;0.33445
4.22;0.7204837449382;0.693661028383838;1.05542727272727;0.337477777777778
4.24;0.722935435733758;0.700514938989899;1.06047272727273;0.339977777777778
4.26;0.725384064616715;0.706719119545455;1.06552424242424;0.34215
4.28;0.727829639369479;0.712786287676768;1.07058181818182;0.344244444444444
4.3;0.730263408108719;0.717844161010101;1.07562727272727;0.345844444444444
4.32;0.732688355180478;0.72454592962963;1.08066666666667;0.348227777777778
4.34;0.735110341883429;0.730068766161616;1.08571212121212;0.350033333333333
4.36;0.737530824868754;0.736182174074074;1.09076666666667;0.352111111111111
4.38;0.739942571498719;0.743851370942761;1.09581515151515;0.354922222222222
4.4;0.742347073189019;0.748758391447812;1.10086060606061;0.356405555555556
4.42;0.744750123970985;0.755543858720539;1.10591515151515;0.358772222222222
4.44;0.747150284942241;0.763539931515152;1.11097575757576;0.3617
4.46;0.7495418347963;0.766343885690236;1.1160303030303;0.362161111111111
4.48;0.751926250124638;0.772274106212121;1.12108181818182;0.364094444444444
4.5;0.754307844063605;0.780553019057239;1.12613939393939;0.367122222222222
4.52;0.756682357607046;0.785202887070707;1.13119393939394;0.368433333333333
4.54;0.759049827672646;0.793021784848485;1.13624545454545;0.371222222222222
4.56;0.761410290886487;0.798095939444445;1.14129393939394;0.372716666666667
4.58;0.763766607276302;0.805141876565657;1.14634545454545;0.375122222222222
4.6;0.766118793015768;0.813145534444444;1.1514;0.377961111111111
4.62;0.76846826940383;0.818292937643098;1.15646060606061;0.379461111111111
4.64;0.770809434823466;0.826779545454545;1.16151515151515;0.3825
4.66;0.773139537315546;0.831536834006734;1.16655757575758;0.383805555555556
4.68;0.775465618472311;0.838757541531987;1.17160303030303;0.386238888888889
4.7;0.777786301529517;0.845845601212121;1.17664848484848;0.3886
4.72;0.780101611483734;0.852254496380472;1.18169393939394;0.390638888888889
4.74;0.782412958920572;0.85737311026936;1.18674242424242;0.392077777777778
4.76;0.784720358916011;0.863785991515152;1.19179393939394;0.3941
4.78;0.7870252058438;0.870880759528619;1.19685151515152;0.396422222222222
4.8;0.789323376448641;0.877202676111111;1.20190606060606;0.398383333333333
4.82;0.791613531437018;0.885001033585859;1.20695454545455;0.401005555555556
4.84;0.793897083660088;0.891632622222222;1.212;0.403088888888889
4.86;0.796176799970359;0.899555105791246;1.21704848484848;0.405744444444444
4.88;0.798451330992918;0.905726724848485;1.22209696969697;0.4076
4.9;0.800719339639559;0.914464679393939;1.22714242424242;0.4106
4.92;0.802983573608171;0.923879015151515;1.23219090909091;0.413888888888889
4.94;0.80524404688331;0.928642042929293;1.23724242424242;0.415083333333333
4.96;0.807498070510446;0.932954961414141;1.24229090909091;0.416072222222222
4.98;0.809747024939023;0.942184555690236;1.24733939393939;0.419244444444444
5;0.811989587544254;0.946915103552189;1.25238484848485;0.420405555555556
5.02;0.814231159410154;0.9560381246633;1.25743939393939;0.423505555555556
5.04;0.816467717867446;0.962980267659933;1.26249393939394;0.425627777777778
5.06;0.818696612531105;0.968278407525252;1.26754242424242;0.427016666666667
5.08;0.820919216855531;0.977099158484849;1.27258787878788;0.42995
5.1;0.823140883539171;0.984371748619529;1.27764242424242;0.432188888888889
5.12;0.825360280375796;0.990718478518518;1.28270303030303;0.434011111111111
5.14;0.827570788678187;1.00182042520202;1.28775454545455;0.437905555555556
5.16;0.829772456430469;1.00898351979798;1.29279696969697;0.440066666666667
5.18;0.831973243766557;1.01370862491582;1.29784848484848;0.441155555555556
5.2;0.834170514134892;1.02111999754209;1.30290303030303;0.443405555555556
5.22;0.836361654108133;1.02814246212121;1.30795454545455;0.445477777777778
5.24;0.838549313595703;1.03923498454545;1.31300909090909;0.4493
5.26;0.840729583158517;1.04749158419192;1.31805757575758;0.451883333333333
5.28;0.842905109485622;1.05416099957912;1.32310606060606;0.453772222222222
5.3;0.845075913170301;1.06342339121212;1.32815454545455;0.456766666666667
5.32;0.847244612216298;1.068959745;1.33320909090909;0.45815
5.34;0.849407322218999;1.07524913969697;1.33826060606061;0.45985
5.36;0.851562778654046;1.08428676934343;1.34330606060606;0.462716666666667
5.38;0.853714889482566;1.09148909989899;1.34835454545455;0.464788888888889
5.4;0.855864953923332;1.09908126893939;1.35340909090909;0.467016666666667
5.42;0.858009120639192;1.10796548505051;1.35846060606061;0.469783333333333
5.44;0.860144853375583;1.11398463104377;1.36350303030303;0.471327777777778
5.46;0.862279872651873;1.12240536454545;1.36855454545455;0.473877777777778
5.48;0.864414173322244;1.13297925882155;1.37361515151515;0.477322222222222
5.5;0.866540106609599;1.14010814814815;1.37866666666667;0.479305555555556
5.52;0.868660258639538;1.14924204599327;1.38371515151515;0.482122222222222
5.54;0.870775925133189;1.15678533272727;1.38876363636364;0.484261111111111
5.56;0.872884593246918;1.16296417993266;1.39380606060606;0.485822222222222
5.58;0.874992613924117;1.17290808468013;1.39885757575758;0.488944444444444
5.6;0.877096200196318;1.17958483585859;1.40390909090909;0.490694444444444
5.62;0.87919537068068;1.18745698141414;1.40896060606061;0.492933333333333
5.64;0.881291399173932;1.19845123316498;1.41401515151515;0.496455555555556
5.66;0.883381790845761;1.20622727555556;1.41906666666667;0.498633333333333
5.68;0.885465321762818;1.21598850915825;1.42411212121212;0.501622222222222
5.7;0.887544520603245;1.22258151255892;1.42915757575758;0.503294444444444
5.72;0.88962189511123;1.22942434813131;1.43420909090909;0.505061111111111
5.74;0.891696205382276;1.24119219843434;1.43926363636364;0.508838888888889
5.76;0.893764982061252;1.25059310868687;1.44431515151515;0.511633333333333
5.78;0.895831962090839;1.25772568020202;1.44937272727273;0.513488888888889
5.8;0.897894678525235;1.26697692242424;1.4544303030303;0.5162
5.82;0.899950684740394;1.27369731469697;1.45948181818182;0.517872222222222
5.84;0.902003702029635;1.28161367656566;1.46453636363636;0.520022222222222
5.86;0.904048831926451;1.29097389545455;1.46958181818182;0.52275
5.88;0.906088563251912;1.29778918811448;1.47462424242424;0.524438888888889
5.9;0.908126586659385;1.30900545676768;1.47967272727273;0.527894444444444
5.92;0.910164123691104;1.31864637181818;1.4847303030303;0.5307
5.94;0.912196300512398;1.32708298851852;1.48978484848485;0.533011111111111
5.96;0.914219497439192;1.33542559848485;1.49482727272727;0.535277777777778
5.98;0.916242245850242;1.34215714478114;1.49987878787879;0.536888888888889
6;0.918264540207978;1.35147046835017;1.50493939393939;0.539522222222222
6.02;0.920279131261002;1.36253462060606;1.50999090909091;0.542844444444444
6.04;0.922282442640134;1.3700454837037;1.51502424242424;0.544744444444444
6.06;0.924284153729745;1.37998684727273;1.52006363636364;0.5476
6.08;0.926286666247923;1.38649864444444;1.52511515151515;0.549083333333333
6.1;0.928287572058325;1.39584006757576;1.53017272727273;0.551677777777778
6.12;0.930280896400124;1.40725904116162;1.53522121212121;0.555083333333333
6.14;0.932267869488188;1.41533611015152;1.54026363636364;0.557161111111111
6.16;0.934253283430488;1.42226385084175;1.54531212121212;0.558777777777778
6.18;0.936234763313712;1.43283509449495;1.55036060606061;0.561816666666667
6.2;0.938211138858139;1.44273967171717;1.55540606060606;0.564583333333333
6.22;0.94018716654947;1.45196608579125;1.56046060606061;0.567072222222222
6.24;0.942161659586793;1.46067950212121;1.56552121212121;0.56935
6.26;0.944128725158397;1.4700248569697;1.57057272727273;0.571866666666667
6.28;0.946091928978115;1.48069775892256;1.57562424242424;0.574888888888889
6.3;0.948052460406872;1.48895130087542;1.58067878787879;0.576961111111111
6.32;0.950010327602918;1.49820437949495;1.58573636363636;0.579411111111111
6.34;0.951960860110068;1.51088815063973;1.59078484848485;0.583177777777778
6.36;0.953907595445462;1.51735111111111;1.59583333333333;0.584533333333333
6.38;0.955850548364561;1.52262846308081;1.60088181818182;0.585427777777778
6.4;0.957789733536986;1.53474817457912;1.6059303030303;0.588944444444444
6.42;0.959726326146909;1.54725332;1.61098181818182;0.592594444444444
6.44;0.961660333970958;1.55879433434343;1.61603636363636;0.595861111111111
6.46;0.963589452504062;1.56752704430976;1.62108787878788;0.598044444444444
6.48;0.965514856703093;1.57483743589226;1.62613939393939;0.599677777777778
6.5;0.967435409158125;1.58542225636364;1.63118787878788;0.60255
6.52;0.969354579119634;1.59639124579125;1.63624242424242;0.605555555555556
6.54;0.971271220199618;1.60483920611111;1.6413;0.607594444444444
6.56;0.973180759533404;1.61424317188552;1.64634848484848;0.609988888888889
6.58;0.975085516566444;1.62300661010101;1.65139393939394;0.612133333333333
6.6;0.976986652396549;1.63518602693603;1.65643939393939;0.615555555555556
6.62;0.978886457915996;1.64592512242424;1.66149090909091;0.618422222222222
6.64;0.980776978918187;1.6539579830303;1.66652727272727;0.620266666666667
6.66;0.982663932593763;1.66484424808081;1.67156363636364;0.623172222222222
6.68;0.98455638951025;1.67525450292929;1.67662424242424;0.625883333333333
6.7;0.986445271797323;1.68037352255892;1.68168484848485;0.626611111111111
6.72;0.98832720931408;1.6914498040404;1.68673636363636;0.629555555555556
6.74;0.990205611793698;1.7017632513468;1.69178787878788;0.632205555555556
6.76;0.992079368841304;1.71391442121212;1.69683636363636;0.635527777777778
6.78;0.993950743039689;1.72752706774411;1.70188787878788;0.639377777777778
6.8;0.995818621737055;1.73746408855219;1.70693939393939;0.641855555555556
6.82;0.997683017967409;1.74503055045455;1.71199090909091;0.64345
6.84;0.999543944691989;1.75231122747475;1.71704242424242;0.644933333333333
6.86;1.00140030157419;1.76281095;1.72209090909091;0.647594444444445
6.88;1.0032554411082;1.77458384888889;1.72714545454545;0.650711111111111
6.9;1.00510714547125;1.78660075888889;1.7322;0.653905555555556
6.92;1.0069543203018;1.79610840947811;1.73725151515152;0.656172222222222
6.94;1.00879919438818;1.80762150991583;1.74230606060606;0.659161111111111
6.96;1.01063956819317;1.81629335643098;1.74735757575758;0.661105555555556
6.98;1.01247766220661;1.82617956888889;1.75241212121212;0.663483333333333
7;1.0143112848831;1.83484694212121;1.75746363636364;0.665411111111111
7.02;1.01613935766528;1.84205640909091;1.76250909090909;0.666805555555556
7.04;1.0179651896327;1.85666212565657;1.76755757575758;0.670866666666667
7.06;1.01978660106788;1.86762540121212;1.77260303030303;0.6736
7.08;1.02160579195344;1.87661222643098;1.77765151515152;0.675611111111111
7.1;1.02342059041219;1.89048702407407;1.78269696969697;0.679372222222222
7.12;1.02523427535982;1.89698540648148;1.78774848484848;0.680472222222222
7.14;1.02704793192696;1.90837299863636;1.79280909090909;0.683316666666667
7.16;1.02885397278818;1.92124216631313;1.79785757575758;0.686683333333333
7.18;1.03065567661564;1.93063960727273;1.80290303030303;0.6888
7.2;1.03245629851636;1.94341654040404;1.80795454545455;0.692111111111111
7.22;1.0342547612512;1.95408802065657;1.81300909090909;0.694661111111111
7.24;1.03604569405869;1.96474551636364;1.81805151515152;0.6972
7.26;1.03783235176061;1.97682235757576;1.82309090909091;0.700233333333333
7.28;1.03962118042646;1.98490246343434;1.82814545454545;0.701838888888889
7.3;1.04140574532771;1.99658538451178;1.83319696969697;0.704711111111111
7.32;1.04318819889536;2.01198919489899;1.83825151515152;0.708883333333333
7.34;1.04496641520648;2.02212552289562;1.84330303030303;0.711188888888889
7.36;1.04674041119733;2.03062144350168;1.84835151515152;0.712911111111111
7.38;1.04851126569858;2.04482570111111;1.8534;0.716627777777778
7.4;1.05028004993785;2.05346392762626;1.85845151515152;0.718383333333333
7.42;1.05204571110267;2.06310620828283;1.86350303030303;0.720483333333333
7.44;1.05380826020218;2.07433147388889;1.86855454545455;0.723127777777778
7.46;1.05556665365714;2.08850275350168;1.87360303030303;0.726788888888889
7.48;1.05732406595176;2.10038051506734;1.87865757575758;0.729638888888889
7.5;1.05907839516585;2.1107811489899;1.88371212121212;0.731966666666667
7.52;1.06082965209796;2.12361262018519;1.88876666666667;0.735127777777778
7.54;1.06257575316143;2.13648764961279;1.89381515151515;0.738294444444444
7.56;1.06431985601071;2.14372800481481;1.89886666666667;0.739505555555556
7.58;1.06606092226061;2.15548166909091;1.90391818181818;0.742266666666667
7.6;1.06779896246661;2.16506534074074;1.9089696969697;0.744272222222222
7.62;1.06953294722444;2.17720868454545;1.91401818181818;0.74715
7.64;1.07126185426713;2.1912414949495;1.91906060606061;0.750666666666667
7.66;1.07298674102914;2.20288698;1.9241;0.753355555555556
7.68;1.07471383035071;2.21282980136364;1.92915454545455;0.75545
7.7;1.07643897472575;2.22604002575758;1.93421212121212;0.75865
7.72;1.07816114810235;2.23650664170034;1.9392696969697;0.760905555555556
7.74;1.07987933149505;2.24769712666667;1.94432424242424;0.7634
7.76;1.08159354035824;2.26307240420875;1.94937575757576;0.767305555555556
7.78;1.08330276437109;2.27350918998316;1.95442121212121;0.769527777777778
7.8;1.08500907192139;2.28508642074074;1.95946666666667;0.772127777777778
7.82;1.08671247294496;2.295998168367;1.96451212121212;0.774494444444444
7.84;1.08841399778246;2.3110110489899;1.96956060606061;0.778233333333333
7.86;1.09011263235037;2.32373157060606;1.97460909090909;0.781188888888889
7.88;1.09181143743761;2.33491646111111;1.97966666666667;0.783616666666667
7.9;1.09350736147976;2.34780067089226;1.98472424242424;0.786605555555556
7.92;1.09520041423236;2.36008393757576;1.98978181818182;0.789383333333333
7.94;1.09688858171626;2.372357225;1.99483333333333;0.79215
7.96;1.09857087366911;2.3860678456229;1.99987575757576;0.795388888888889
7.98;1.10025034026814;2.39468607505051;2.00491818181818;0.796922222222222
8;1.1019279977455;2.40693414383838;2.00996363636364;0.799655555555556
8.02;1.10360485554468;2.42115766717172;2.01501515151515;0.803033333333333
8.04;1.1052809129752;2.43463162909091;2.02007272727273;0.80615
8.06;1.10695316422658;2.44858843333333;2.02512727272727;0.809416666666667
8.08;1.10862162368109;2.46013482057239;2.03017878787879;0.811877777777778
8.1;1.11028630563771;2.47050637626263;2.03522727272727;0.813944444444444
8.12;1.11194722431283;2.48277116111111;2.04027272727273;0.816627777777778
8.14;1.1136063839797;2.49831384861953;2.04532121212121;0.820377777777778
8.16;1.11526478223609;2.51112016323232;2.05037575757576;0.823216666666667
8.18;1.116922418311;2.52611596292929;2.05543636363636;0.826761111111111
8.2;1.11857632104038;2.5369794483165;2.06049393939394;0.828944444444444
8.22;1.12022452738187;2.54932211079125;2.06554242424242;0.831605555555556
8.24;1.12187100848768;2.56235946585859;2.07059393939394;0.834483333333333
8.26;1.12351281263183;2.56945749723906;2.07563939393939;0.835422222222222
8.28;1.12515389296267;2.58266299373737;2.08069090909091;0.838338888888889
8.3;1.12679032049136;2.59556714227273;2.08573636363636;0.84115
8.32;1.12842505493148;2.60913754292929;2.09078484848485;0.844166666666667
8.34;1.13005810020803;2.62365252181818;2.09583636363636;0.847477777777778
8.36;1.13168750575739;2.63480462861953;2.10088484848485;0.849694444444445
8.38;1.1333142606627;2.64661755888889;2.10593333333333;0.852116666666667
8.4;1.13493837353385;2.6619288759596;2.11098181818182;0.855655555555556
8.42;1.13656082542668;2.67528772962963;2.11603333333333;0.858555555555556
8.44;1.13818162014564;2.69204233171717;2.12108787878788;0.862533333333333
8.46;1.13979785345232;2.70374323863636;2.12613636363636;0.864883333333333
8.48;1.14141244654458;2.7141832352862;2.13118787878788;0.866822222222222
8.5;1.14302540314912;2.72922785185185;2.13624242424242;0.870222222222222
8.52;1.14463576231365;2.74216028639731;2.14129696969697;0.872938888888889
8.54;1.14624256927339;2.75651590757576;2.14634848484849;0.8761
8.56;1.14784487539677;2.77028536565657;2.15139393939394;0.879066666666667
8.58;1.14944461824184;2.78532980008418;2.15643939393939;0.882427777777778
8.6;1.15103988898233;2.79896255353535;2.16147878787879;0.885333333333333
8.62;1.15263453285038;2.80969214390572;2.16652424242424;0.887311111111111
8.64;1.15422568241847;2.82177810296296;2.17156666666667;0.889711111111111
8.66;1.15581621213466;2.83682321747475;2.17661515151515;0.893033333333333
8.68;1.1574070733604;2.85134439434343;2.18167272727273;0.896177777777778
8.7;1.15899445685261;2.86192894747475;2.18672727272727;0.898077777777778
8.72;1.16057837514308;2.87745950569024;2.19177878787879;0.901522222222222
8.74;1.16215978860332;2.88981027276094;2.1968303030303;0.903961111111111
8.76;1.16374059796766;2.90352529328283;2.20188787878788;0.906816666666667
8.78;1.16531891231738;2.91628929818182;2.20694545454545;0.909366666666667
8.8;1.16689190921908;2.92787523104377;2.21199393939394;0.911544444444444
8.82;1.16846337763965;2.94397191287879;2.21704545454545;0.915116666666667
8.84;1.17003332089637;2.95781619777778;2.2221;0.917977777777778
8.86;1.17159986429221;2.97034196902357;2.22715151515152;0.920422222222222
8.88;1.17316395746771;2.98585528934343;2.23220303030303;0.923783333333333
8.9;1.17472467200331;2.99999694855219;2.23725151515152;0.926711111111111
8.92;1.1762857583461;3.0120511069697;2.24230909090909;0.928983333333333
8.94;1.17784441149624;3.02663593796296;2.24736666666667;0.932027777777778
8.96;1.17939598048633;3.0377320219697;2.25240909090909;0.933994444444445
8.98;1.18094607610663;3.05371886060606;2.25745454545455;0.937455555555556
9;1.18249377264881;3.069051875;2.2625;0.940705555555556
9.02;1.18404000492137;3.08195173090909;2.26754848484849;0.9432
9.04;1.18558385005029;3.09600400099327;2.27259696969697;0.946038888888889
9.06;1.18712531539498;3.10806372055556;2.27764545454545;0.948261111111111
9.08;1.18866440828085;3.12182369917508;2.28269393939394;0.950994444444444
9.1;1.19020297939229;3.13780888867004;2.28774848484849;0.954394444444445
9.12;1.1917391869387;3.15212716750842;2.29280303030303;0.957277777777778
9.14;1.1932721193002;3.16910996828283;2.29785454545455;0.960961111111111
9.16;1.19479995297542;3.1836440396633;2.30289696969697;0.963894444444444
9.18;1.19632545593539;3.19368684276094;2.30793939393939;0.965461111111111
9.2;1.19784954995531;3.2094540719697;2.31298484848485;0.96875
9.22;1.19937497777525;3.2269068589899;2.31804242424242;0.972533333333333
9.24;1.20089717031803;3.24120109104377;2.32309696969697;0.975355555555556
9.26;1.20241613880515;3.25461489304714;2.32814848484849;0.977905555555556
9.28;1.20393462177881;3.26674563531987;2.33320606060606;0.980061111111111
9.3;1.20545080245748;3.28238481227273;2.33826363636364;0.983261111111111
9.32;1.20696287506019;3.30150513814815;2.34331515151515;0.987494444444444
9.34;1.2084717597411;3.3167402020202;2.34836363636364;0.990555555555556
9.36;1.20997837111876;3.32949111474748;2.35341212121212;0.992866666666667
9.38;1.21148452060977;3.34329759222222;2.35846666666667;0.995483333333333
9.4;1.21298840502562;3.35533664383838;2.36352121212121;0.997566666666667
9.42;1.21449003116887;3.37134547542088;2.36857575757576;1.00082222222222
9.44;1.21598850757905;3.38599723939394;2.37362727272727;1.00366666666667
9.46;1.21748384502659;3.40110641052189;2.37867575757576;1.00663888888889
9.48;1.21897694977828;3.41748629097643;2.38372424242424;1.00997777777778
9.5;1.22046693427263;3.42919018885522;2.3887696969697;1.01192777777778
9.52;1.22195648779376;3.44523760348485;2.39382121212121;1.01515
9.54;1.22344293428327;3.46012488195286;2.3988696969697;1.01802222222222
9.56;1.22492539404772;3.47284134166667;2.40391212121212;1.02025
9.58;1.22640654830202;3.48937109723906;2.40895757575758;1.02358888888889
9.6;1.22788728720089;3.50833057540404;2.41400909090909;1.02762777777778
9.62;1.22936760934588;3.52066993111111;2.41906666666667;1.02971666666667
9.64;1.23084308841351;3.53673049427609;2.42411515151515;1.03288888888889
9.66;1.23231639364972;3.55074653818182;2.42916363636364;1.03545555555556
9.68;1.2337884138368;3.56797783166667;2.43421515151515;1.03895
9.7;1.23525827036501;3.58407890037037;2.43926666666667;1.04210555555556
9.72;1.23672684938281;3.59455102232323;2.44432121212121;1.04361666666667
9.74;1.2381915178217;3.60995701952862;2.4493696969697;1.04655555555556
9.76;1.2396514124647;3.62570939949495;2.45440909090909;1.04958888888889
9.78;1.24111005487124;3.64099584299663;2.45945151515152;1.05247777777778
9.8;1.24256744741237;3.65546774154882;2.46449696969697;1.05512222222222
9.82;1.24402621265039;3.67175247424242;2.46955454545455;1.05827777777778
9.84;1.24548198086435;3.68640581838384;2.47460909090909;1.06095555555556
9.86;1.24693476203624;3.70286150249158;2.47966060606061;1.06414444444444
9.88;1.24838456609675;3.71572594414141;2.48470909090909;1.06629444444444
9.9;1.24983400795052;3.73460933060606;2.48976363636364;1.07016111111111
9.92;1.25128135196294;3.75052237878788;2.49481818181818;1.07316666666667
9.94;1.25272487253163;3.7651371162963;2.49986666666667;1.07579444444444
9.96;1.25416631235193;3.78365326481482;2.50491515151515;1.07952777777778
9.98;1.25560826743982;3.7995844769697;2.50997272727273;1.08251111111111
10;1.25704900838504;3.81234656944445;2.51503333333333;1.08458333333333
10.02;1.25848423314153;3.82889077368687;2.52008181818182;1.08772777777778
10.04;1.25991654135067;3.84387711434343;2.52512727272727;1.09042222222222
10.06;1.26134765938726;3.85871744808081;2.53017575757576;1.09306666666667
10.08;1.26277673225155;3.87452720915825;2.53522424242424;1.09597777777778
10.1;1.2642037657806;3.88718011818182;2.54027272727273;1.09798888888889
10.12;1.26563218471266;3.90681945925926;2.54533333333333;1.10196111111111
10.14;1.26705771266196;3.92501632318182;2.55039090909091;1.10551666666667
10.16;1.26847780217434;3.93655938939394;2.55543636363636;1.10719444444444
10.18;1.26989587789192;3.95502276454546;2.56048181818182;1.11081111111111
10.2;1.27131279540686;3.97126784301347;2.5655303030303;1.11379444444444
10.22;1.27272770810688;3.9846469079798;2.57057878787879;1.11596666666667
10.24;1.27414146914539;4.00023640151515;2.5756303030303;1.11875
10.26;1.27555408057685;4.01691172649832;2.58068484848485;1.12182777777778
10.28;1.27696385425289;4.03680207742424;2.58573636363636;1.12579444444444
10.3;1.27837079935402;4.05395619632997;2.59078484848485;1.12898888888889
10.32;1.27977745319245;4.06829273653199;2.59583939393939;1.13138888888889
10.34;1.28118128959272;4.08319023646465;2.60089090909091;1.13393888888889
10.36;1.28258147726999;4.0963837750505;2.60593636363636;1.13601111111111
10.38;1.28397970716268;4.11365054828283;2.61098181818182;1.13920555555556
10.4;1.2853751467177;4.12976084215488;2.61602424242424;1.14207222222222
10.42;1.28677031544033;4.14556499474747;2.62107272727273;1.14484444444444
10.44;1.28816437606563;4.16291150111111;2.62612424242424;1.14803333333333
10.46;1.28955733051461;4.1799709420202;2.63117878787879;1.15113333333333
10.48;1.29094751397666;4.19261394195286;2.6362303030303;1.15301111111111
10.5;1.29233576751129;4.20867444282828;2.64128181818182;1.15582222222222
10.52;1.29372375857788;4.23074631158249;2.64633939393939;1.16027222222222
10.54;1.29510650618021;4.24802113272727;2.65138484848485;1.1634
10.56;1.2964848581485;4.26491064217172;2.65642121212121;1.16641666666667
10.58;1.29786627859737;4.27996003762626;2.66147575757576;1.16891666666667
10.6;1.29924909925865;4.29859322914141;2.66654242424242;1.17238333333333
10.62;1.30062835969829;4.31262412380471;2.67160303030303;1.17458888888889
10.64;1.302003247798;4.3255432210101;2.67665454545455;1.17648888888889
10.66;1.30337542510486;4.34115740474748;2.68170303030303;1.17911666666667
10.68;1.30474654406456;4.35905471878788;2.68675454545455;1.18235555555556
10.7;1.30611414399236;4.3751932;2.6918;1.18511111111111
10.72;1.30747987614469;4.39472772424242;2.69684545454545;1.18877777777778
10.74;1.30884456419847;4.41197889520202;2.70189393939394;1.19181666666667
10.76;1.31020820988323;4.42559861333333;2.70694545454545;1.19386666666667
10.78;1.31156999857043;4.44328099493266;2.71199696969697;1.19700555555556
10.8;1.31292830482072;4.45842718599327;2.71704242424242;1.19945555555556
10.82;1.31428721099647;4.47553210962963;2.72209696969697;1.20242222222222
10.84;1.31564427305194;4.49359881144781;2.72715151515152;1.20563888888889
10.86;1.3169986840517;4.51045029996633;2.73220303030303;1.20852222222222
10.88;1.31835045226623;4.5303378116835;2.73725151515152;1.21221111111111
10.9;1.31969877618163;4.54613867757576;2.74229393939394;1.2148
10.92;1.32104609322217;4.55961684468013;2.74733939393939;1.21676111111111
10.94;1.32239321257482;4.57539446853535;2.75239090909091;1.21932777777778
10.96;1.32373690667626;4.59156636171717;2.75743636363636;1.22199444444444
10.98;1.32507960308611;4.60808241548822;2.76248484848485;1.22474444444444
11;1.32641969475897;4.62782491700337;2.7675303030303;1.22834444444444
11.02;1.32775879623404;4.64364627122896;2.77257878787879;1.23089444444444
11.04;1.32909771125484;4.66447473203704;2.77763333333333;1.23476111111111
11.06;1.33043323378206;4.68373764217172;2.78268181818182;1.23820555555556
11.08;1.33176777509852;4.69626325925926;2.78773333333333;1.23986111111111
11.1;1.33310133675271;4.71479354107744;2.79278787878788;1.24309444444444
11.12;1.33443551608912;4.73341003755892;2.79785151515152;1.24633888888889
11.14;1.33576393357016;4.74996999055556;2.8029;1.24903888888889
11.16;1.33709058869908;4.76886312973064;2.80794848484849;1.25234444444444
11.18;1.33841707560447;4.78413253542088;2.81300303030303;1.25468888888889
11.2;1.33974339262501;4.79837268646465;2.81806363636364;1.25675555555556
11.22;1.34106636760769;4.81719262772727;2.82311818181818;1.26001666666667
11.24;1.34238601147956;4.83169929074074;2.82816666666667;1.26214444444444
11.26;1.34370391618631;4.85178559983165;2.83321515151515;1.26572222222222
11.28;1.34502166530159;4.86988997291246;2.8382696969697;1.26877222222222
11.3;1.34633610332014;4.88490011262626;2.84331818181818;1.27101111111111
11.32;1.34764960328462;4.9088734862963;2.8483696969697;1.27557222222222
11.34;1.34896295301442;4.92829799459596;2.85342727272727;1.27893888888889
11.36;1.35027222403347;4.94455093942761;2.85847575757576;1.28147777777778
11.38;1.35157899876629;4.96043927626263;2.86352121212121;1.28391666666667
11.4;1.35288328475281;4.97611191343434;2.86856363636364;1.28629444444444
11.42;1.35418821867561;4.99483305712121;2.87361515151515;1.28945
11.44;1.35549223323896;5.01395631727273;2.8786696969697;1.2927
11.46;1.3567937693053;5.02488796161616;2.88372121212121;1.29383333333333
11.48;1.35809283433284;5.04656445713805;2.8887696969697;1.29772777777778
11.5;1.35939021397963;5.0649488969697;2.89381818181818;1.30076666666667
11.52;1.3606851353862;5.08045758207071;2.89886363636364;1.30306111111111
11.54;1.36197682969294;5.09795514882155;2.90390303030303;1.30586111111111
11.56;1.36326840812293;5.11155820259259;2.90894848484849;1.30765555555556
11.58;1.36455909475206;5.12814057412458;2.91399696969697;1.31020555555556
11.6;1.36584811765634;5.14657758080808;2.91904545454545;1.31322222222222
11.62;1.3671370255782;5.16697147277778;2.9241;1.31672777777778
11.64;1.36842427435467;5.18783737545455;2.92915454545455;1.32034444444444
11.66;1.36970986825175;5.20664159449495;2.93420909090909;1.32342777777778
11.68;1.37099381151897;5.22337604262626;2.93926363636364;1.32597777777778
11.7;1.37227534011881;5.24317813090909;2.94431515151515;1.3293
11.72;1.37355522850485;5.25834036648148;2.94936666666667;1.33143888888889
11.74;1.37483271456183;5.27464058779461;2.95441515151515;1.33386111111111
11.76;1.37610933606153;5.29286106074074;2.95946666666667;1.33676111111111
11.78;1.37738432987649;5.31113285757576;2.96451818181818;1.33966666666667
11.8;1.37865922691734;5.32933188013468;2.96957575757576;1.34254444444444
11.82;1.37993250066505;5.34632345925926;2.97463333333333;1.34511111111111
11.84;1.38120339380604;5.36145761968013;2.97968787878788;1.34720555555556
11.86;1.38247115287336;5.38191775727273;2.98473636363636;1.35063333333333
11.88;1.3837365472467;5.39828562727273;2.98978181818182;1.35302777777778
11.9;1.38500034242053;5.4144779180303;2.99482727272727;1.35537222222222
11.92;1.38626330003144;5.43645335744108;2.99987575757576;1.35915555555556
11.94;1.38752466459216;5.45479581649832;3.00492424242424;1.36202222222222
11.96;1.38878444011648;5.47118451146465;3.00997272727273;1.36439444444444
11.98;1.390042630603;5.4920805990404;3.01502121212121;1.36788333333333
12;1.39129848624135;5.50746899962963;3.02006666666667;1.36999444444444
12.02;1.39255427238188;5.52702394606061;3.02511818181818;1.37313333333333
12.04;1.39380848350126;5.54504331656566;3.0301696969697;1.37588333333333
12.06;1.39506112354537;5.55948118920875;3.03522121212121;1.37773888888889
12.08;1.39631294646935;5.58137160737374;3.04027575757576;1.38143333333333
12.1;1.39756170611725;5.59994234878788;3.04532424242424;1.3843
12.12;1.39880741199983;5.61608090574074;3.05036666666667;1.38656111111111
12.14;1.40005156802972;5.63246756616162;3.05540909090909;1.38887777777778
12.16;1.40129567065166;5.64687835060606;3.06045757575758;1.3907
12.18;1.40253822740528;5.66654751956229;3.06550606060606;1.39381111111111
12.2;1.40377998657197;5.69018720673401;3.07055757575758;1.39788888888889
12.22;1.40502169272693;5.70864621580808;3.07561515151515;1.40068333333333
12.24;1.40626185895965;5.72930984989899;3.08067272727273;1.40401111111111
12.26;1.40749974740498;5.74448714848485;3.08572727272727;1.40598888888889
12.28;1.40873610537688;5.75752541686869;3.09078181818182;1.40743888888889
12.3;1.40997093665508;5.77833767787879;3.09583636363636;1.41078333333333
12.32;1.41120424500537;5.79642703818182;3.10089090909091;1.41345555555556
12.34;1.41243529615123;5.81453912092593;3.10594242424242;1.41612777777778
12.36;1.41366335942876;5.83557013276095;3.11098787878788;1.41950555555556
12.38;1.41489138885394;5.85456296639731;3.11603939393939;1.42237777777778
12.4;1.41612085333098;5.87211391784512;3.12110303030303;1.42488888888889
12.42;1.41734807366962;5.89025905282828;3.12616363636364;1.42753888888889
12.44;1.41857158924556;5.90419498737374;3.13121515151515;1.42916666666667
12.46;1.41979141180416;5.92443066338384;3.13625757575758;1.43231666666667
12.48;1.42100974820834;5.94304158666667;3.1413;1.43506666666667
12.5;1.42222587123709;5.9608696536027;3.14633939393939;1.43762222222222
12.52;1.42344197700775;5.98159204868687;3.15138484848485;1.44086666666667
12.54;1.42465879285044;6.00000499579125;3.15643939393939;1.44354444444444
12.56;1.42587485802808;6.01606809424242;3.16149696969697;1.44565
12.58;1.42708871889462;6.03606003249158;3.16655151515152;1.44869444444444
12.6;1.42829965526492;6.05468341555556;3.1716;1.45140555555556
12.62;1.42950912704168;6.07486561040404;3.17664848484849;1.45448333333333
12.64;1.43071641310444;6.09193819417508;3.18169393939394;1.45681111111111
12.66;1.43192296717059;6.11048078914142;3.18674242424242;1.45948333333333
12.68;1.43312734430426;6.1314911442761;3.19178787878788;1.46273888888889
12.7;1.4343309947032;6.14251301757576;3.19683636363636;1.46360555555556
12.72;1.43553391924623;6.16022441234007;3.20188787878788;1.46606111111111
12.74;1.43673539850019;6.18139628282828;3.20693939393939;1.46933333333333
12.76;1.43793399703944;6.19774850521886;3.21198484848485;1.47145555555556
12.78;1.43913187924666;6.21735966703704;3.21703333333333;1.47434444444444
12.8;1.44032761052126;6.2360572816835;3.22207878787879;1.47701111111111
12.82;1.44152334747109;6.24922505159933;3.2271303030303;1.47836111111111
12.84;1.44271837235562;6.26913541606061;3.23218484848485;1.4813
12.86;1.44391125570007;6.28718777616162;3.23723636363636;1.48379444444444
12.88;1.44510200346016;6.30879607117845;3.24228484848485;1.48712222222222
12.9;1.44629276194545;6.33247628407408;3.24733939393939;1.49092777777778
12.92;1.447482816822;6.34842706048822;3.25239696969697;1.49290555555556
12.94;1.44867003362207;6.36204718585859;3.25744848484849;1.49433333333333
12.96;1.44985513168785;6.38382330882155;3.26249696969697;1.49767222222222
12.98;1.45103882695849;6.4041157949495;3.26754545454545;1.50065555555556
13;1.45222183199276;6.41924463387205;3.27259696969697;1.50242222222222